Workbook

Sheet rawdata
A1: STATE_NAME | B1: Lg_Dist_Code | C1: DISTRICT_NAME | D1: MICRO_MANUFACTURING | E1: SMALL_MANUFACTURING | F1: MEDIUM_MANUFACTURING | G1: TOTAL_MANUFACTURING | H1: MICRO_SERVICE | I1: SMALL_SERVICE | J1: MEDIUM_SERVICE | K1: TOTAL_SERVICE | L1: TOTAL
A2: ANDHRA PRADESH | B2: 745 | C2: Alluri Sitharama Raju | D2: 1418 | E2: 4 | F2: 0 | G2: 1422 | H2: 405 | I2: 5 | J2: 0 | K2: 410 | L2: 1832
A3: ANDHRA PRADESH | B3: 744 | C3: Anakapalli | D3: 7908 | E3: 86 | F3: 2 | G3: 7996 | H3: 2875 | I3: 26 | J3: 2 | K3: 2903 | L3: 10899
A4: ANDHRA PRADESH | B4: 502 | C4: ANANTHAPUR | D4: 33925 | E4: 633 | F4: 24 | G4: 34582 | H4: 10470 | I4: 358 | J4: 32 | K4: 10860 | L4: 45442
A5: ANDHRA PRADESH | B5: 753 | C5: Annamayya | D5: 9035 | E5: 96 | F5: 4 | G5: 9135 | H5: 2986 | I5: 19 | J5: 0 | K5: 3005 | L5: 12140
A6: ANDHRA PRADESH | B6: 750 | C6: Bapatla | D6: 8631 | E6: 92 | F6: 1 | G6: 8724 | H6: 2206 | I6: 23 | J6: 3 | K6: 2232 | L6: 10956
A7: ANDHRA PRADESH | B7: 503 | C7: CHITOOR | D7: 26870 | E7: 692 | F7: 28 | G7: 27590 | H7: 8756 | I7: 359 | J7: 37 | K7: 9152 | L7: 36742
A8: ANDHRA PRADESH | B8: 505 | C8: EAST GODAVARI | D8: 34655 | E8: 1213 | F8: 85 | G8: 35953 | H8: 9961 | I8: 648 | J8: 96 | K8: 10705 | L8: 46658
A9: ANDHRA PRADESH | B9: 748 | C9: Eluru | D9: 11597 | E9: 133 | F9: 5 | G9: 11735 | H9: 2636 | I9: 58 | J9: 3 | K9: 2697 | L9: 14432
A10: ANDHRA PRADESH | B10: 506 | C10: GUNTUR | D10: 37169 | E10: 1255 | F10: 90 | G10: 38514 | H10: 10154 | I10: 1336 | J10: 157 | K10: 11647 | L10: 50161
A11: ANDHRA PRADESH | B11: 746 | C11: Kakinada | D11: 11978 | E11: 153 | F11: 10 | G11: 12141 | H11: 2608 | I11: 48 | J11: 2 | K11: 2658 | L11: 14799
A12: ANDHRA PRADESH | B12: 747 | C12: Konaseema | D12: 9654 | E12: 130 | F12: 5 | G12: 9789 | H12: 3148 | I12: 31 | J12: 6 | K12: 3185 | L12: 12974
A13: ANDHRA PRADESH | B13: 510 | C13: KRISHNA | D13: 41521 | E13: 1732 | F13: 129 | G13: 43382 | H13: 11711 | I13: 908 | J13: 101 | K13: 12720 | L13: 56102
A14: ANDHRA PRADESH | B14: 511 | C14: KURNOOL | D14: 31673 | E14: 736 | F14: 31 | G14: 32440 | H14: 6286 | I14: 307 | J14: 34 | K14: 6627 | L14: 39067
A15: ANDHRA PRADESH | B15: 755 | C15: Nandyal | D15: 11085 | E15: 115 | F15: 2 | G15: 11202 | H15: 1975 | I15: 22 | J15: 1 | K15: 1998 | L15: 13200
A16: ANDHRA PRADESH | B16: 749 | C16: NTR | D16: 14001 | E16: 200 | F16: 8 | G16: 14209 | H16: 3842 | I16: 71 | J16: 7 | K16: 3920 | L16: 18129
A17: ANDHRA PRADESH | B17: 751 | C17: Palnadu | D17: 10047 | E17: 111 | F17: 1 | G17: 10159 | H17: 2012 | I17: 48 | J17: 2 | K17: 2062 | L17: 12221
A18: ANDHRA PRADESH | B18: 743 | C18: Parvathipuram Manyam | D18: 2525 | E18: 28 | F18: 1 | G18: 2554 | H18: 525 | I18: 14 | J18: 0 | K18: 539 | L18: 3093
A19: ANDHRA PRADESH | B19: 517 | C19: PRAKASAM | D19: 26333 | E19: 624 | F19: 16 | G19: 26973 | H19: 7151 | I19: 389 | J19: 45 | K19: 7585 | L19: 34558
A20: ANDHRA PRADESH | B20: 515 | C20: SPSR NELLORE | D20: 30251 | E20: 819 | F20: 45 | G20: 31115 | H20: 7996 | I20: 467 | J20: 49 | K20: 8512 | L20: 39627
A21: ANDHRA PRADESH | B21: 754 | C21: Sri Sathya Sai | D21: 7968 | E21: 66 | F21: 2 | G21: 8036 | H21: 5523 | I21: 38 | J21: 1 | K21: 5562 | L21: 13598
A22: ANDHRA PRADESH | B22: 519 | C22: SRIKAKULAM | D22: 15977 | E22: 397 | F22: 10 | G22: 16384 | H22: 4833 | I22: 221 | J22: 15 | K22: 5069 | L22: 21453
A23: ANDHRA PRADESH | B23: 752 | C23: Tirupati | D23: 13134 | E23: 130 | F23: 6 | G23: 13270 | H23: 4176 | I23: 43 | J23: 4 | K23: 4223 | L23: 17493
A24: ANDHRA PRADESH | B24: 520 | C24: VISAKHAPATNAM | D24: 40901 | E24: 1648 | F24: 124 | G24: 42673 | H24: 8279 | I24: 660 | J24: 110 | K24: 9049 | L24: 51722
A25: ANDHRA PRADESH | B25: 521 | C25: VIZIANAGARAM | D25: 15833 | E25: 322 | F25: 8 | G25: 16163 | H25: 3197 | I25: 155 | J25: 20 | K25: 3372 | L25: 19535
A26: ANDHRA PRADESH | B26: 523 | C26: WEST GODAVARI | D26: 34147 | E26: 1338 | F26: 126 | G26: 35611 | H26: 7794 | I26: 696 | J26: 76 | K26: 8566 | L26: 44177
A27: ANDHRA PRADESH | B27: 504 | C27: Y.S.R | D27: 25101 | E27: 608 | F27: 13 | G27: 25722 | H27: 5845 | I27: 282 | J27: 22 | K27: 6149 | L27: 31871
A28: ARUNACHAL PRADESH | B28: 628 | C28: ANJAW | D28: 56 | E28: 0 | F28: 0 | G28: 56 | H28: 21 | I28: 0 | J28: 0 | K28: 21 | L28: 77
A29: ARUNACHAL PRADESH | B29: 229 | C29: CHANGLANG | D29: 324 | E29: 4 | F29: 0 | G29: 328 | H29: 309 | I29: 12 | J29: 0 | K29: 321 | L29: 649
A30: ARUNACHAL PRADESH | B30: 230 | C30: DIBANG VALLEY | D30: 54 | E30: 1 | F30: 0 | G30: 55 | H30: 13 | I30: 0 | J30: 0 | K30: 13 | L30: 68
A31: ARUNACHAL PRADESH | B31: 231 | C31: EAST KAMENG | D31: 151 | E31: 5 | F31: 0 | G31: 156 | H31: 61 | I31: 0 | J31: 0 | K31: 61 | L31: 217
A32: ARUNACHAL PRADESH | B32: 232 | C32: EAST SIANG | D32: 424 | E32: 10 | F32: 0 | G32: 434 | H32: 159 | I32: 7 | J32: 0 | K32: 166 | L32: 600
A33: ARUNACHAL PRADESH | B33: 718 | C33: KAMLE | D33: 70 | E33: 0 | F33: 0 | G33: 70 | H33: 38 | I33: 0 | J33: 0 | K33: 38 | L33: 108
A34: ARUNACHAL PRADESH | B34: 677 | C34: KRA DAADI | D34: 65 | E34: 0 | F34: 0 | G34: 65 | H34: 28 | I34: 1 | J34: 0 | K34: 29 | L34: 94
A35: ARUNACHAL PRADESH | B35: 233 | C35: KURUNG KUMEY | D35: 85 | E35: 1 | F35: 0 | G35: 86 | H35: 30 | I35: 0 | J35: 0 | K35: 30 | L35: 116
A36: ARUNACHAL PRADESH | B36: 724 | C36: LEPARADA | D36: 70 | E36: 0 | F36: 0 | G36: 70 | H36: 26 | I36: 0 | J36: 0 | K36: 26 | L36: 96
A37: ARUNACHAL PRADESH | B37: 234 | C37: LOHIT | D37: 304 | E37: 6 | F37: 0 | G37: 310 | H37: 133 | I37: 7 | J37: 0 | K37: 140 | L37: 450
A38: ARUNACHAL PRADESH | B38: 666 | C38: LONGDING | D38: 75 | E38: 3 | F38: 0 | G38: 78 | H38: 35 | I38: 0 | J38: 0 | K38: 35 | L38: 113
A39: ARUNACHAL PRADESH | B39: 235 | C39: LOWER DIBANG VALLEY | D39: 255 | E39: 4 | F39: 0 | G39: 259 | H39: 88 | I39: 2 | J39: 0 | K39: 90 | L39: 349
A40: ARUNACHAL PRADESH | B40: 719 | C40: LOWER SIANG | D40: 59 | E40: 1 | F40: 0 | G40: 60 | H40: 42 | I40: 2 | J40: 0 | K40: 44 | L40: 104
...

Sheet topdistricts
A1: STATE_NAME | B1: Lg_Dist_Code | C1: DISTRICT_NAME | D1: MICRO_MANUFACTURING | E1: SMALL_MANUFACTURING | F1: MEDIUM_MANUFACTURING | G1: TOTAL_MANUFACTURING | H1: MICRO_SERVICE | I1: SMALL_SERVICE | J1: MEDIUM_SERVICE | K1: TOTAL_SERVICE | L1: TOTAL
A2: MAHARASHTRA | B2: 490 | C2: PUNE | D2: 429047 | E2: 7334 | F2: 643 | G2: 437024 | H2: 115383 | I2: 5846 | J2: 783 | K2: 122012 | L2: 559036
A3: MAHARASHTRA | B3: 497 | C3: THANE | D3: 309088 | E3: 5423 | F3: 482 | G3: 314993 | H3: 80367 | I3: 4680 | J3: 481 | K3: 85528 | L3: 400521
A4: GUJARAT | B4: 438 | C4: AHMADABAD | D4: 207426 | E4: 6654 | F4: 721 | G4: 214801 | H4: 106460 | I4: 9241 | J4: 1133 | K4: 116834 | L4: 331635
A5: KARNATAKA | B5: 525 | C5: BENGALURU (URBAN) | D5: 229054 | E5: 9380 | F5: 1026 | G5: 239460 | H5: 82038 | I5: 5976 | J5: 779 | K5: 88793 | L5: 328253
A6: RAJASTHAN | B6: 102 | C6: JAIPUR | D6: 203924 | E6: 4451 | F6: 411 | G6: 208786 | H6: 104443 | I6: 4701 | J6: 477 | K6: 109621 | L6: 318407
A7: GUJARAT | B7: 459 | C7: SURAT | D7: 143826 | E7: 3836 | F7: 340 | G7: 148002 | H7: 152193 | I7: 11605 | J7: 876 | K7: 164674 | L7: 312676
A8: MAHARASHTRA | B8: 483 | C8: MUMBAI SUBURBAN | D8: 215296 | E8: 5760 | F8: 853 | G8: 221909 | H8: 62011 | I8: 3976 | J8: 613 | K8: 66600 | L8: 288509
A9: TAMIL NADU | B9: 568 | C9: CHENNAI | D9: 196042 | E9: 6882 | F9: 770 | G9: 203694 | H9: 47972 | I9: 3608 | J9: 488 | K9: 52068 | L9: 255762
A10: MAHARASHTRA | B10: 482 | C10: MUMBAI | D10: 176085 | E10: 8538 | F10: 1431 | G10: 186054 | H10: 56602 | I10: 6509 | J10: 1323 | K10: 64434 | L10: 250488
A11: MAHARASHTRA | B11: 487 | C11: NASHIK | D11: 136487 | E11: 2421 | F11: 146 | G11: 139054 | H11: 40167 | I11: 1697 | J11: 201 | K11: 42065 | L11: 181119
A12: TAMIL NADU | B12: 569 | C12: COIMBATORE | D12: 106750 | E12: 2322 | F12: 193 | G12: 109265 | H12: 57104 | I12: 3485 | J12: 408 | K12: 60997 | L12: 170262
A13: MAHARASHTRA | B13: 484 | C13: NAGPUR | D13: 122446 | E13: 2719 | F13: 263 | G13: 125428 | H13: 35485 | I13: 1688 | J13: 255 | K13: 37428 | L13: 162856
... A197: ANDHRA PRADESH | B197: 504 | C197: Y.S.R | D197: 25101 | E197: 608 | F197: 13 | G197: 25722 | H197: 5845 | I197: 282 | J197: 22 | K197: 6149 | L197: 31871
A198: UTTAR PRADESH | B198: 123 | C198: AZAMGARH | D198: 24851 | E198: 348 | F198: 12 | G198: 25211 | H198: 6596 | I198: 50 | J198: 0 | K198: 6646 | L198: 31857
A199: WEST BENGAL | B199: 704 | C199: PASCHIM BARDHAMAN | D199: 25406 | E199: 885 | F199: 62 | G199: 26353 | H199: 4993 | I199: 249 | J199: 42 | K199: 5284 | L199: 31637
A200: JAMMU AND KASHMIR | B200: 2 | C200: BUDGAM | D200: 16419 | E200: 94 | F200: 2 | G200: 16515 | H200: 14942 | I200: 50 | J200: 2 | K200: 14994 | L200: 31509
A201: GUJARAT | B201: 451 | C201: MAHESANA | D201: 21821 | E201: 892 | F201: 68 | G201: 22781 | H201: 7004 | I201: 1103 | J201: 226 | K201: 8333 | L201: 31114
A202: HARYANA | B202: 74 | C202: SIRSA | D202: 22845 | E202: 500 | F202: 35 | G202: 23380 | H202: 6932 | I202: 247 | J202: 49 | K202: 7228 | L202: 30608
A203: MAHARASHTRA | B203: 498 | C203: WARDHA | D203: 22626 | E203: 245 | F203: 9 | G203: 22880 | H203: 7468 | I203: 163 | J203: 75 | K203: 7706 | L203: 30586
A204: TAMIL NADU | B204: 585 | C204: SIVAGANGA | D204: 23630 | E204: 208 | F204: 5 | G204: 23843 | H204: 6554 | I204: 107 | J204: 13 | K204: 6674 | L204: 30517
A205: TELANGANA | B205: 508 | C205: KARIMNAGAR | D205: 23358 | E205: 398 | F205: 14 | G205: 23770 | H205: 6446 | I205: 265 | J205: 21 | K205: 6732 | L205: 30502
A206: HARYANA | B206: 66 | C206: KAITHAL | D206: 22946 | E206: 355 | F206: 11 | G206: 23312 | H206: 6840 | I206: 284 | J206: 48 | K206: 7172 | L206: 30484
A207: MADHYA PRADESH | B207: 403 | C207: DHAR | D207: 23727 | E207: 411 | F207: 24 | G207: 24162 | H207: 5874 | I207: 351 | J207: 69 | K207: 6294 | L207: 30456
A208: KARNATAKA | B208: 528 | C208: BALLARI | D208: 24378 | E208: 779 | F208: 56 | G208: 25213 | H208: 4817 | I208: 356 | J208: 56 | K208: 5229 | L208: 30442
A209: KARNATAKA | B209: 549 | C209: UDUPI | D209: 22767 | E209: 432 | F209: 17 | G209: 23216 | H209: 6690 | I209: 348 | J209: 39 | K209: 7077 | L209: 30293
A210: KARNATAKA | B210: 530 | C210: VIJAYAPURA | D210: 23880 | E210: 525 | F210: 31 | G210: 24436 | H210: 5626 | I210: 165 | J210: 15 | K210: 5806 | L210: 30242
... A218: HARYANA | B218: 65 | C218: JIND | D218: 21284 | E218: 461 | F218: 20 | G218: 21765 | H218: 6728 | I218: 270 | J218: 24 | K218: 7022 | L218: 28787
A219: BIHAR | B219: 206 | C219: MADHUBANI | D219: 21311 | E219: 280 | F219: 7 | G219: 21598 | H219: 7112 | I219: 44 | J219: 0 | K219: 7156 | L219: 28754
A220: UTTAR PRADESH | B220: 146 | C220: GHAZIPUR | D220: 21976 | E220: 240 | F220: 4 | G220: 22220 | H220: 6346 | I220: 53 | J220: 2 | K220: 6401 | L220: 28621
A221: BIHAR | B221: 195 | C221: DARBHANGA | D221: 21421 | E221: 384 | F221: 15 | G221: 21820 | H221: 6468 | I221: 50 | J221: 7 | K221: 6525 | L221: 28345
A222: KARNATAKA | B222: 550 | C222: UTTAR KANNAD | D222: 21851 | E222: 285 | F222: 7 | G222: 22143 | H222: 5993 | I222: 122 | J222: 4 | K222: 6119 | L222: 28262
A223: CHHATTISGARH | B223: 375 | C223: BILASPUR | D223: 21662 | E223: 631 | F223: 41 | G223: 22334 | H223: 5354 | I223: 253 | J223: 42 | K223: 5649 | L223: 27983
A224: PUNJAB | B224: 32 | C224: GURDASPUR | D224: 21194 | E224: 307 | F224: 15 | G224: 21516 | H224: 6178 | I224: 169 | J224: 10 | K224: 6357 | L224: 27873
A225: TAMIL NADU | B225: 583 | C225: RAMANATHAPURAM | D225: 20768 | E225: 187 | F225: 5 | G225: 20960 | H225: 6799 | I225: 94 | J225: 6 | K225: 6899 | L225: 27859
A226: RAJASTHAN | B226: 112 | C226: RAJSAMAND | D226: 18478 | E226: 194 | F226: 4 | G226: 18676 | H226: 8791 | I226: 228 | J226: 4 | K226: 9023 | L226: 27699
A227: PUNJAB | B227: 38 | C227: MOGA | D227: 20348 | E227: 282 | F227: 8 | G227: 20638 | H227: 6895 | I227: 114 | J227: 14 | K227: 7023 | L227: 27661
A228: BIHAR | B228: 191 | C228: BEGUSARAI | D228: 19577 | E228: 346 | F228: 14 | G228: 19937 | H228: 7385 | I228: 96 | J228: 14 | K228: 7495 | L228: 27432
A229: KERALA | B229: 560 | C229: KOTTAYAM | D229: 19222 | E229: 705 | F229: 38 | G229: 19965 | H229: 7036 | I229: 297 | J229: 43 | K229: 7376 | L229: 27341
A230: MADHYA PRADESH | B230: 423 | C230: RATLAM | D230: 20997 | E230: 385 | F230: 17 | G230: 21399 | H230: 5504 | I230: 247 | J230: 30 | K230: 5781 | L230: 27180
...

Sheet Sheet2
A2: ANDHRA PRADESH
A3: ARUNACHAL PRADESH
A4: ASSAM
A5: BIHAR
A6: CHHATTISGARH
A7: GOA
A8: GUJARAT
A9: HARYANA
A10: HIMACHAL PRADESH
A11: JHARKHAND
A12: KARNATAKA
A13: KERALA
... A37: THE DADRA AND NAGAR HAVELI AND DAMAN AND DIU

Sheet dashboard
A1: msme sector analysis dashboard - india
A3: total msmes in india | B3: total manufacturing msmes | C3: total service msmes
A4: =SUM(rawdata!L:L) -> 21180783 | B4: =SUM(rawdata!G:G) -> 15627666 | C4: =SUM(rawdata!K:K) -> 5553117
E5: manufacturing | F5: service
E6: =B4 -> 15627666 | F6: =C4 -> 5553117

Sheet analysis
A1: state | B1: total msme | C1: total manufacturing | D1: total service | E1: manufacturing vs service ratio
A2: MAHARASHTRA | B2: =SUMIF(rawdata!A:A,A2,rawdata!L:L) -> 3670797 | C2: =SUMIF(rawdata!A:A,A2,rawdata!G:G) -> 2831118 | D2: =SUMIF(rawdata!A:A,A2,rawdata!K:K) -> 839679 | E2: =C2/B2 -> 0.77125431
A3: TAMIL NADU | B3: =SUMIF(rawdata!A:A,A3,rawdata!L:L) -> 2147720 | C3: =SUMIF(rawdata!A:A,A3,rawdata!G:G) -> 1511001 | D3: =SUMIF(rawdata!A:A,A3,rawdata!K:K) -> 636719 | E3: =C3/B3 -> 0.70353724
A4: UTTAR PRADESH | B4: =SUMIF(rawdata!A:A,A4,rawdata!L:L) -> 2001698 | C4: =SUMIF(rawdata!A:A,A4,rawdata!G:G) -> 1440711 | D4: =SUMIF(rawdata!A:A,A4,rawdata!K:K) -> 560987 | E4: =C4/B4 -> 0.71974444
A5: RAJASTHAN | B5: =SUMIF(rawdata!A:A,A5,rawdata!L:L) -> 1540402 | C5: =SUMIF(rawdata!A:A,A5,rawdata!G:G) -> 1088374 | D5: =SUMIF(rawdata!A:A,A5,rawdata!K:K) -> 452028 | E5: =C5/B5 -> 0.70655193
A6: GUJARAT | B6: =SUMIF(rawdata!A:A,A6,rawdata!L:L) -> 1536720 | C6: =SUMIF(rawdata!A:A,A6,rawdata!G:G) -> 990727 | D6: =SUMIF(rawdata!A:A,A6,rawdata!K:K) -> 545993 | E6: =C6/B6 -> 0.64470235
A7: KARNATAKA | B7: =SUMIF(rawdata!A:A,A7,rawdata!L:L) -> 1195371 | C7: =SUMIF(rawdata!A:A,A7,rawdata!G:G) -> 908686 | D7: =SUMIF(rawdata!A:A,A7,rawdata!K:K) -> 286685 | E7: =C7/B7 -> 0.76017069
A8: MADHYA PRADESH | B8: =SUMIF(rawdata!A:A,A8,rawdata!L:L) -> 994877 | C8: =SUMIF(rawdata!A:A,A8,rawdata!G:G) -> 782706 | D8: =SUMIF(rawdata!A:A,A8,rawdata!K:K) -> 212171 | E8: =C8/B8 -> 0.78673645
A9: BIHAR | B9: =SUMIF(rawdata!A:A,A9,rawdata!L:L) -> 868351 | C9: =SUMIF(rawdata!A:A,A9,rawdata!G:G) -> 648522 | D9: =SUMIF(rawdata!A:A,A9,rawdata!K:K) -> 219829 | E9: =C9/B9 -> 0.74684315
A10: WEST BENGAL | B10: =SUMIF(rawdata!A:A,A10,rawdata!L:L) -> 835442 | C10: =SUMIF(rawdata!A:A,A10,rawdata!G:G) -> 607107 | D10: =SUMIF(rawdata!A:A,A10,rawdata!K:K) -> 228335 | E10: =C10/B10 -> 0.72668958
A11: PUNJAB | B11: =SUMIF(rawdata!A:A,A11,rawdata!L:L) -> 795588 | C11: =SUMIF(rawdata!A:A,A11,rawdata!G:G) -> 577252 | D11: =SUMIF(rawdata!A:A,A11,rawdata!K:K) -> 218336 | E11: =C11/B11 -> 0.7255665
A12: TELANGANA | B12: =SUMIF(rawdata!A:A,A12,rawdata!L:L) -> 725691 | C12: =SUMIF(rawdata!A:A,A12,rawdata!G:G) -> 573841 | D12: =SUMIF(rawdata!A:A,A12,rawdata!K:K) -> 151850 | E12: =C12/B12 -> 0.79075116
A13: HARYANA | B13: =SUMIF(rawdata!A:A,A13,rawdata!L:L) -> 709631 | C13: =SUMIF(rawdata!A:A,A13,rawdata!G:G) -> 530289 | D13: =SUMIF(rawdata!A:A,A13,rawdata!K:K) -> 179342 | E13: =C13/B13 -> 0.74727429
A14: ANDHRA PRADESH | B14: =SUMIF(rawdata!A:A,A14,rawdata!L:L) -> 672881 | C14: =SUMIF(rawdata!A:A,A14,rawdata!G:G) -> 527474 | D14: =SUMIF(rawdata!A:A,A14,rawdata!K:K) -> 145407 | E14: =C14/B14 -> 0.78390384 | F14: =EXACT(A14,MSME_UDYAM[[#This Row],[STATE_NAME]]) -> TRUE
A15: DELHI | B15: =SUMIF(rawdata!A:A,A15,rawdata!L:L) -> 529253 | C15: =SUMIF(rawdata!A:A,A15,rawdata!G:G) -> 368468 | D15: =SUMIF(rawdata!A:A,A15,rawdata!K:K) -> 160785 | E15: =C15/B15 -> 0.69620389
A16: KERALA | B16: =SUMIF(rawdata!A:A,A16,rawdata!L:L) -> 499787 | C16: =SUMIF(rawdata!A:A,A16,rawdata!G:G) -> 360218 | D16: =SUMIF(rawdata!A:A,A16,rawdata!K:K) -> 139569 | E16: =C16/B16 -> 0.72074304
A17: ODISHA | B17: =SUMIF(rawdata!A:A,A17,rawdata!L:L) -> 458522 | C17: =SUMIF(rawdata!A:A,A17,rawdata!G:G) -> 359582 | D17: =SUMIF(rawdata!A:A,A17,rawdata!K:K) -> 98940 | E17: =C17/B17 -> 0.78421973
A18: JHARKHAND | B18: =SUMIF(rawdata!A:A,A18,rawdata!L:L) -> 358717 | C18: =SUMIF(rawdata!A:A,A18,rawdata!G:G) -> 288053 | D18: =SUMIF(rawdata!A:A,A18,rawdata!K:K) -> 70664 | E18: =C18/B18 -> 0.80300906
A19: ASSAM | B19: =SUMIF(rawdata!A:A,A19,rawdata!L:L) -> 356090 | C19: =SUMIF(rawdata!A:A,A19,rawdata!G:G) -> 247272 | D19: =SUMIF(rawdata!A:A,A19,rawdata!K:K) -> 108818 | E19: =C19/B19 -> 0.69440872
A20: JAMMU AND KASHMIR | B20: =SUMIF(rawdata!A:A,A20,rawdata!L:L) -> 354271 | C20: =SUMIF(rawdata!A:A,A20,rawdata!G:G) -> 256972 | D20: =SUMIF(rawdata!A:A,A20,rawdata!K:K) -> 97299 | E20: =C20/B20 -> 0.72535432
A21: CHHATTISGARH | B21: =SUMIF(rawdata!A:A,A21,rawdata!L:L) -> 294358 | C21: =SUMIF(rawdata!A:A,A21,rawdata!G:G) -> 240827 | D21: =SUMIF(rawdata!A:A,A21,rawdata!K:K) -> 53531 | E21: =C21/B21 -> 0.81814321
A22: UTTARAKHAND | B22: =SUMIF(rawdata!A:A,A22,rawdata!L:L) -> 203203 | C22: =SUMIF(rawdata!A:A,A22,rawdata!G:G) -> 161703 | D22: =SUMIF(rawdata!A:A,A22,rawdata!K:K) -> 41500 | E22: =C22/B22 -> 0.79577073
A23: HIMACHAL PRADESH | B23: =SUMIF(rawdata!A:A,A23,rawdata!L:L) -> 123947 | C23: =SUMIF(rawdata!A:A,A23,rawdata!G:G) -> 102786 | D23: =SUMIF(rawdata!A:A,A23,rawdata!K:K) -> 21161 | E23: =C23/B23 -> 0.8292738
A24: MANIPUR | B24: =SUMIF(rawdata!A:A,A24,rawdata!L:L) -> 56349 | C24: =SUMIF(rawdata!A:A,A24,rawdata!G:G) -> 29992 | D24: =SUMIF(rawdata!A:A,A24,rawdata!K:K) -> 26357 | E24: =C24/B24 -> 0.53225434
A25: TRIPURA | B25: =SUMIF(rawdata!A:A,A25,rawdata!L:L) -> 43866 | C25: =SUMIF(rawdata!A:A,A25,rawdata!G:G) -> 30312 | D25: =SUMIF(rawdata!A:A,A25,rawdata!K:K) -> 13554 | E25: =C25/B25 -> 0.69101354
A26: GOA | B26: =SUMIF(rawdata!A:A,A26,rawdata!L:L) -> 43014 | C26: =SUMIF(rawdata!A:A,A26,rawdata!G:G) -> 35688 | D26: =SUMIF(rawdata!A:A,A26,rawdata!K:K) -> 7326 | E26: =C26/B26 -> 0.82968336
... A37: LAKSHADWEEP | B37: =SUMIF(rawdata!A:A,A37,rawdata!L:L) -> 732 | C37: =SUMIF(rawdata!A:A,A37,rawdata!G:G) -> 620 | D37: =SUMIF(rawdata!A:A,A37,rawdata!K:K) -> 112 | E37: =C37/B37 -> 0.84699454
A40: top 10 distrtic by total msme
A41: district | B41: state | C41: total msme
